Traceback (most recent call last):
  File "/home/rm/.cache/pypoetry/virtualenvs/przetwarzanie-danych-zlozonych-kjty6M6D-py3.9/lib/python3.9/site-packages/jupyter_cache/executors/utils.py", line 51, in single_nb_execution
    executenb(
  File "/home/rm/.cache/pypoetry/virtualenvs/przetwarzanie-danych-zlozonych-kjty6M6D-py3.9/lib/python3.9/site-packages/nbclient/client.py", line 1204, in execute
    return NotebookClient(nb=nb, resources=resources, km=km, **kwargs).execute()
  File "/home/rm/.cache/pypoetry/virtualenvs/przetwarzanie-danych-zlozonych-kjty6M6D-py3.9/lib/python3.9/site-packages/nbclient/util.py", line 84, in wrapped
    return just_run(coro(*args, **kwargs))
  File "/home/rm/.cache/pypoetry/virtualenvs/przetwarzanie-danych-zlozonych-kjty6M6D-py3.9/lib/python3.9/site-packages/nbclient/util.py", line 62, in just_run
    return loop.run_until_complete(coro)
  File "/usr/lib/python3.9/asyncio/base_events.py", line 647, in run_until_complete
    return future.result()
  File "/home/rm/.cache/pypoetry/virtualenvs/przetwarzanie-danych-zlozonych-kjty6M6D-py3.9/lib/python3.9/site-packages/nbclient/client.py", line 663, in async_execute
    await self.async_execute_cell(
  File "/home/rm/.cache/pypoetry/virtualenvs/przetwarzanie-danych-zlozonych-kjty6M6D-py3.9/lib/python3.9/site-packages/nbclient/client.py", line 965, in async_execute_cell
    await self._check_raise_for_error(cell, cell_index, exec_reply)
  File "/home/rm/.cache/pypoetry/virtualenvs/przetwarzanie-danych-zlozonych-kjty6M6D-py3.9/lib/python3.9/site-packages/nbclient/client.py", line 862, in _check_raise_for_error
    raise CellExecutionError.from_cell_and_msg(cell, exec_reply_content)
nbclient.exceptions.CellExecutionError: An error occurred while executing the following cell:
------------------
from hiclass import LocalClassifierPerNode
from sklearn.ensemble import RandomForestClassifier

X_train = df.iloc[:,:-1]
Y_train = df.iloc[:,-1].tolist()

rf = RandomForestClassifier()
classifier = LocalClassifierPerNode(local_classifier=rf)
classifier.fit(X_train, Y_train)
------------------

[0;31m---------------------------------------------------------------------------[0m
[0;31mModuleNotFoundError[0m                       Traceback (most recent call last)
Cell [0;32mIn [4], line 1[0m
[0;32m----> 1[0m [38;5;28;01mfrom[39;00m [38;5;21;01mhiclass[39;00m [38;5;28;01mimport[39;00m LocalClassifierPerNode
[1;32m      2[0m [38;5;28;01mfrom[39;00m [38;5;21;01msklearn[39;00m[38;5;21;01m.[39;00m[38;5;21;01mensemble[39;00m [38;5;28;01mimport[39;00m RandomForestClassifier
[1;32m      4[0m X_train [38;5;241m=[39m df[38;5;241m.[39miloc[:,:[38;5;241m-[39m[38;5;241m1[39m]

[0;31mModuleNotFoundError[0m: No module named 'hiclass'
ModuleNotFoundError: No module named 'hiclass'

