Traceback (most recent call last):
  File "/Users/kamiltagowski/Library/Caches/pypoetry/virtualenvs/przetwarzanie-danych-zlozonych-tgGM1AJj-py3.9/lib/python3.9/site-packages/jupyter_cache/executors/utils.py", line 51, in single_nb_execution
    executenb(
  File "/Users/kamiltagowski/Library/Caches/pypoetry/virtualenvs/przetwarzanie-danych-zlozonych-tgGM1AJj-py3.9/lib/python3.9/site-packages/nbclient/client.py", line 1204, in execute
    return NotebookClient(nb=nb, resources=resources, km=km, **kwargs).execute()
  File "/Users/kamiltagowski/Library/Caches/pypoetry/virtualenvs/przetwarzanie-danych-zlozonych-tgGM1AJj-py3.9/lib/python3.9/site-packages/nbclient/util.py", line 84, in wrapped
    return just_run(coro(*args, **kwargs))
  File "/Users/kamiltagowski/Library/Caches/pypoetry/virtualenvs/przetwarzanie-danych-zlozonych-tgGM1AJj-py3.9/lib/python3.9/site-packages/nbclient/util.py", line 62, in just_run
    return loop.run_until_complete(coro)
  File "/Users/kamiltagowski/.pyenv/versions/3.9.6/lib/python3.9/asyncio/base_events.py", line 642, in run_until_complete
    return future.result()
  File "/Users/kamiltagowski/Library/Caches/pypoetry/virtualenvs/przetwarzanie-danych-zlozonych-tgGM1AJj-py3.9/lib/python3.9/site-packages/nbclient/client.py", line 663, in async_execute
    await self.async_execute_cell(
  File "/Users/kamiltagowski/Library/Caches/pypoetry/virtualenvs/przetwarzanie-danych-zlozonych-tgGM1AJj-py3.9/lib/python3.9/site-packages/nbclient/client.py", line 965, in async_execute_cell
    await self._check_raise_for_error(cell, cell_index, exec_reply)
  File "/Users/kamiltagowski/Library/Caches/pypoetry/virtualenvs/przetwarzanie-danych-zlozonych-tgGM1AJj-py3.9/lib/python3.9/site-packages/nbclient/client.py", line 862, in _check_raise_for_error
    raise CellExecutionError.from_cell_and_msg(cell, exec_reply_content)
nbclient.exceptions.CellExecutionError: An error occurred while executing the following cell:
------------------
pd.DataFrame(stream_2, columns=["x"]).to_csv("../../../pdz-2022-lab8-template/data/stream1.csv", header=True, index=False)
------------------

[0;31m---------------------------------------------------------------------------[0m
[0;31mNameError[0m                                 Traceback (most recent call last)
Cell [0;32mIn [8], line 1[0m
[0;32m----> 1[0m pd[38;5;241m.[39mDataFrame(stream_2, columns[38;5;241m=[39m[[38;5;124m"[39m[38;5;124mx[39m[38;5;124m"[39m])[38;5;241m.[39mto_csv([38;5;124m"[39m[38;5;124m../../../pdz-2022-lab8-template/data/stream1.csv[39m[38;5;124m"[39m, header[38;5;241m=[39m[38;5;28;01mTrue[39;00m, index[38;5;241m=[39m[38;5;28;01mFalse[39;00m)

[0;31mNameError[0m: name 'stream_2' is not defined
NameError: name 'stream_2' is not defined

